<?xml version="1.0" ?>
<!-- Generated using onshape-to-robot -->
<!-- Onshape document_id: 67456fa7f995371c54d81f33 -->
<robot name="climbbot3">

<!-- <link name="base_link"/>

<joint name="base_to_assm7" type="fixed">
  <parent link="base_link"/>
  <child link="assembly_7"/>
</joint> -->
  <!-- Link assembly_7 -->
  <link name="assembly_7">
    <inertial>
      <origin xyz="0.0943103 0.0690414 0.0321994" rpy="0 0 0"/>
      <mass value="0.236044"/>
      <inertia ixx="0.000367069" ixy="-4.60522e-07" ixz="-4.24165e-05" iyy="0.000675507" iyz="6.48999e-07" izz="0.000898441"/>
    </inertial>
    <!-- Part servo_arm_horn_25t_aluminium -->
    <visual>
      <origin xyz="0.180853 0.0191578 0.0276276" rpy="0 -0 0"/>
      <geometry>
        <mesh filename="package://climbbot3_description/climbbot3/assets/servo_arm_horn_25t_aluminium.stl"/>
      </geometry>
      <material name="servo_arm_horn_25t_aluminium_material">
        <color rgba="0.231373 0.380392 0.705882 1.0"/>
      </material>
    </visual>
    <collision>
      <origin xyz="0.180853 0.0191578 0.0276276" rpy="0 -0 0"/>
      <geometry>
        <mesh filename="package://climbbot3_description/climbbot3/assets/servo_arm_horn_25t_aluminium.stl"/>
      </geometry>
    </collision>
    <!-- Part component2 -->
    <visual>
      <origin xyz="0.0187847 0.0410598 0.0136672" rpy="1.21962e-16 0.275165 6.8081e-17"/>
      <geometry>
        <mesh filename="package://climbbot3_description/climbbot3/assets/component2.stl"/>
      </geometry>
      <material name="component2_material">
        <color rgba="0.615686 0.811765 0.929412 1.0"/>
      </material>
    </visual>
    <collision>
      <origin xyz="0.0187847 0.0410598 0.0136672" rpy="1.21962e-16 0.275165 6.8081e-17"/>
      <geometry>
        <mesh filename="package://climbbot3_description/climbbot3/assets/component2.stl"/>
      </geometry>
    </collision>
    <!-- Part component2_2 -->
    <visual>
      <origin xyz="0.0187847 0.10846 0.0136672" rpy="1.21962e-16 0.275165 6.8081e-17"/>
      <geometry>
        <mesh filename="package://climbbot3_description/climbbot3/assets/component2.stl"/>
      </geometry>
      <material name="component2_2_material">
        <color rgba="0.615686 0.811765 0.929412 1.0"/>
      </material>
    </visual>
    <collision>
      <origin xyz="0.0187847 0.10846 0.0136672" rpy="1.21962e-16 0.275165 6.8081e-17"/>
      <geometry>
        <mesh filename="package://climbbot3_description/climbbot3/assets/component2.stl"/>
      </geometry>
    </collision>
    <!-- Part component707 -->
    <visual>
      <origin xyz="0.0281825 0.0707432 -0.000322443" rpy="0 -0 0"/>
      <geometry>
        <mesh filename="package://climbbot3_description/climbbot3/assets/component707.stl"/>
      </geometry>
      <material name="component707_material">
        <color rgba="0.980392 0.713725 0.00392157 1.0"/>
      </material>
    </visual>
    <collision>
      <origin xyz="0.0281825 0.0707432 -0.000322443" rpy="0 -0 0"/>
      <geometry>
        <mesh filename="package://climbbot3_description/climbbot3/assets/component707.stl"/>
      </geometry>
    </collision>
    <!-- Part servo_arm_horn_25t_aluminium_2 -->
    <visual>
      <origin xyz="0.180853 0.1192 0.0276276" rpy="0 -0 3.14159"/>
      <geometry>
        <mesh filename="package://climbbot3_description/climbbot3/assets/servo_arm_horn_25t_aluminium.stl"/>
      </geometry>
      <material name="servo_arm_horn_25t_aluminium_2_material">
        <color rgba="0.231373 0.380392 0.705882 1.0"/>
      </material>
    </visual>
    <collision>
      <origin xyz="0.180853 0.1192 0.0276276" rpy="0 -0 3.14159"/>
      <geometry>
        <mesh filename="package://climbbot3_description/climbbot3/assets/servo_arm_horn_25t_aluminium.stl"/>
      </geometry>
    </collision>
  </link>
  <!-- Link assembly_9 -->
  <link name="assembly_9">
    <inertial>
      <origin xyz="0.00950296 0.0152428 -0.0306495" rpy="0 0 0"/>
      <mass value="0.117321"/>
      <inertia ixx="5.92776e-05" ixy="3.58792e-07" ixz="-6.45305e-08" iyy="3.37113e-05" iyz="2.68677e-06" izz="6.38145e-05"/>
    </inertial>
    <!-- Part ds3225mg_servo_25kg_4_8_6_8v -->
    <visual>
      <origin xyz="0 0 0" rpy="-1.63941e-45 -2.31229e-43 5.3455e-57"/>
      <geometry>
        <mesh filename="package://climbbot3_description/climbbot3/assets/ds3225mg_servo_25kg_4_8_6_8v.stl"/>
      </geometry>
      <material name="ds3225mg_servo_25kg_4_8_6_8v_material">
        <color rgba="0.615686 0.811765 0.929412 1.0"/>
      </material>
    </visual>
    <collision>
      <origin xyz="0 0 0" rpy="-1.63941e-45 -2.31229e-43 5.3455e-57"/>
      <geometry>
        <mesh filename="package://climbbot3_description/climbbot3/assets/ds3225mg_servo_25kg_4_8_6_8v.stl"/>
      </geometry>
    </collision>
    <!-- Part ds3225mg_servo_25kg_4_8_6_8v_2 -->
    <visual>
      <origin xyz="-0.0005625 0.0598 -0.0323" rpy="-1.5708 2.16053e-15 2.5091e-14"/>
      <geometry>
        <mesh filename="package://climbbot3_description/climbbot3/assets/ds3225mg_servo_25kg_4_8_6_8v.stl"/>
      </geometry>
      <material name="ds3225mg_servo_25kg_4_8_6_8v_2_material">
        <color rgba="0.615686 0.811765 0.929412 1.0"/>
      </material>
    </visual>
    <collision>
      <origin xyz="-0.0005625 0.0598 -0.0323" rpy="-1.5708 2.16053e-15 2.5091e-14"/>
      <geometry>
        <mesh filename="package://climbbot3_description/climbbot3/assets/ds3225mg_servo_25kg_4_8_6_8v.stl"/>
      </geometry>
    </collision>
    <!-- Part servomount1 -->
    <visual>
      <origin xyz="0.0593875 0.042 -0.112549" rpy="1.5708 1.5708 0"/>
      <geometry>
        <mesh filename="package://climbbot3_description/climbbot3/assets/servomount1.stl"/>
      </geometry>
      <material name="servomount1_material">
        <color rgba="0.231373 0.380392 0.705882 1.0"/>
      </material>
    </visual>
    <collision>
      <origin xyz="0.0593875 0.042 -0.112549" rpy="1.5708 1.5708 0"/>
      <geometry>
        <mesh filename="package://climbbot3_description/climbbot3/assets/servomount1.stl"/>
      </geometry>
    </collision>
  </link>
  <!-- Link assembly_13 -->
  <link name="assembly_13">
    <inertial>
      <origin xyz="-0.0497036 -0.0466015 -0.0305687" rpy="0 0 0"/>
      <mass value="0.316303"/>
      <inertia ixx="0.00107614" ixy="0.000141442" ixz="-1.55941e-05" iyy="0.000345613" iyz="-1.32864e-05" izz="0.00123509"/>
    </inertial>
    <!-- Part part_20 -->
    <visual>
      <origin xyz="-0.035 0.0055 -0.03171" rpy="-3.14159 1.5708 0"/>
      <geometry>
        <mesh filename="package://climbbot3_description/climbbot3/assets/part_20.stl"/>
      </geometry>
      <material name="part_20_material">
        <color rgba="0.917647 0.917647 0.917647 1.0"/>
      </material>
    </visual>
    <collision>
      <origin xyz="-0.035 0.0055 -0.03171" rpy="-3.14159 1.5708 0"/>
      <geometry>
        <mesh filename="package://climbbot3_description/climbbot3/assets/part_20.stl"/>
      </geometry>
    </collision>
    <!-- Part part_22 -->
    <visual>
      <origin xyz="-0.099256 0.00775 -0.0732163" rpy="-7.30767e-16 -0.423747 3.14159"/>
      <geometry>
        <mesh filename="package://climbbot3_description/climbbot3/assets/part_22.stl"/>
      </geometry>
      <material name="part_22_material">
        <color rgba="0.972549 0.529412 0.00392157 1.0"/>
      </material>
    </visual>
    <collision>
      <origin xyz="-0.099256 0.00775 -0.0732163" rpy="-7.30767e-16 -0.423747 3.14159"/>
      <geometry>
        <mesh filename="package://climbbot3_description/climbbot3/assets/part_22.stl"/>
      </geometry>
    </collision>
    <!-- Part spur_gear__23_teeth -->
    <visual>
      <origin xyz="-0.035 0.0065 -0.0317099" rpy="-2.94618e-13 1.36934 3.14159"/>
      <geometry>
        <mesh filename="package://climbbot3_description/climbbot3/assets/spur_gear__23_teeth.stl"/>
      </geometry>
      <material name="spur_gear__23_teeth_material">
        <color rgba="0.615686 0.811765 0.929412 1.0"/>
      </material>
    </visual>
    <collision>
      <origin xyz="-0.035 0.0065 -0.0317099" rpy="-2.94618e-13 1.36934 3.14159"/>
      <geometry>
        <mesh filename="package://climbbot3_description/climbbot3/assets/spur_gear__23_teeth.stl"/>
      </geometry>
    </collision>
    <!-- Part spur_gear__22_teeth -->
    <visual>
      <origin xyz="-0.099256 0.00775 -0.0732163" rpy="-1.29102e-14 -0.423747 3.14159"/>
      <geometry>
        <mesh filename="package://climbbot3_description/climbbot3/assets/spur_gear__22_teeth.stl"/>
      </geometry>
      <material name="spur_gear__22_teeth_material">
        <color rgba="0.647059 0.647059 0.647059 1.0"/>
      </material>
    </visual>
    <collision>
      <origin xyz="-0.099256 0.00775 -0.0732163" rpy="-1.29102e-14 -0.423747 3.14159"/>
      <geometry>
        <mesh filename="package://climbbot3_description/climbbot3/assets/spur_gear__22_teeth.stl"/>
      </geometry>
    </collision>
    <!-- Part servo_arm_horn_25t_aluminium_3 -->
    <visual>
      <origin xyz="4.33681e-19 0 0.00105" rpy="-3.14159 -7.53975e-30 1.35143e-30"/>
      <geometry>
        <mesh filename="package://climbbot3_description/climbbot3/assets/servo_arm_horn_25t_aluminium.stl"/>
      </geometry>
      <material name="servo_arm_horn_25t_aluminium_3_material">
        <color rgba="0.231373 0.380392 0.705882 1.0"/>
      </material>
    </visual>
    <collision>
      <origin xyz="4.33681e-19 0 0.00105" rpy="-3.14159 -7.53975e-30 1.35143e-30"/>
      <geometry>
        <mesh filename="package://climbbot3_description/climbbot3/assets/servo_arm_horn_25t_aluminium.stl"/>
      </geometry>
    </collision>
    <!-- Part part_17 -->
    <visual>
      <origin xyz="-0.0390272 0.0055 -0.0504324" rpy="-1.50665e-13 1.14705 3.14159"/>
      <geometry>
        <mesh filename="package://climbbot3_description/climbbot3/assets/part_17.stl"/>
      </geometry>
      <material name="part_17_material">
        <color rgba="0.231373 0.380392 0.705882 1.0"/>
      </material>
    </visual>
    <collision>
      <origin xyz="-0.0390272 0.0055 -0.0504324" rpy="-1.50665e-13 1.14705 3.14159"/>
      <geometry>
        <mesh filename="package://climbbot3_description/climbbot3/assets/part_17.stl"/>
      </geometry>
    </collision>
  </link>
  <!-- Link part_1 -->
  <link name="part_1">
    <inertial>
      <origin xyz="1.38472e-05 7.99599e-06 -0.0930872" rpy="0 0 0"/>
      <mass value="0.147279"/>
      <inertia ixx="0.000468632" ixy="3.96188e-08" ixz="1.39731e-07" iyy="0.000468614" iyz="6.37723e-08" izz="9.32972e-05"/>
    </inertial>
    <!-- Part part_1 -->
    <visual>
      <origin xyz="0 -1.38778e-17 -0.18" rpy="1.5708 6.42508e-31 -1.26218e-29"/>
      <geometry>
        <mesh filename="package://climbbot3_description/climbbot3/assets/part_1.stl"/>
      </geometry>
      <material name="part_1_material">
        <color rgba="0.615686 0.811765 0.929412 1.0"/>
      </material>
    </visual>
    <collision>
      <origin xyz="0 -1.38778e-17 -0.18" rpy="1.5708 6.42508e-31 -1.26218e-29"/>
      <geometry>
        <mesh filename="package://climbbot3_description/climbbot3/assets/part_1.stl"/>
      </geometry>
    </collision>
  </link>
  <!-- Link part_4 -->
  <link name="part_4">
    <inertial>
      <origin xyz="-3.06039e-07 -9.19232e-06 -0.0853006" rpy="0 0 0"/>
      <mass value="0.111767"/>
      <inertia ixx="0.000294934" ixy="-2.53805e-10" ixz="-3.63143e-09" iyy="0.000294916" iyz="-7.85505e-08" izz="5.00057e-05"/>
    </inertial>
    <!-- Part part_4 -->
    <visual>
      <origin xyz="0 0 -0.18" rpy="1.5708 1.18557e-30 0"/>
      <geometry>
        <mesh filename="package://climbbot3_description/climbbot3/assets/part_4.stl"/>
      </geometry>
      <material name="part_4_material">
        <color rgba="0.647059 0.647059 0.647059 1.0"/>
      </material>
    </visual>
    <collision>
      <origin xyz="0 0 -0.18" rpy="1.5708 1.18557e-30 0"/>
      <geometry>
        <mesh filename="package://climbbot3_description/climbbot3/assets/part_4.stl"/>
      </geometry>
    </collision>
  </link>
  <!-- Link assembly_12 -->
  <link name="assembly_12">
    <inertial>
      <origin xyz="-2.19526e-06 0.00540004 -0.0130509" rpy="0 0 0"/>
      <mass value="0.156296"/>
      <inertia ixx="0.000776836" ixy="-5.10682e-10" ixz="-8.26793e-08" iyy="0.000766427" iyz="-6.26958e-05" izz="5.24529e-05"/>
    </inertial>
    <!-- Part gripper_hook -->
    <visual>
      <origin xyz="-2.33147e-15 0.0419282 0.045" rpy="-3.7605e-15 5.41699e-15 6.12323e-17"/>
      <geometry>
        <mesh filename="package://climbbot3_description/climbbot3/assets/gripper_hook.stl"/>
      </geometry>
      <material name="gripper_hook_material">
        <color rgba="0.615686 0.811765 0.929412 1.0"/>
      </material>
    </visual>
    <collision>
      <origin xyz="-2.33147e-15 0.0419282 0.045" rpy="-3.7605e-15 5.41699e-15 6.12323e-17"/>
      <geometry>
        <mesh filename="package://climbbot3_description/climbbot3/assets/gripper_hook.stl"/>
      </geometry>
    </collision>
    <!-- Part part_6 -->
    <visual>
      <origin xyz="0 -6.93889e-18 -0.184" rpy="1.5708 7.28393e-31 0"/>
      <geometry>
        <mesh filename="package://climbbot3_description/climbbot3/assets/part_6.stl"/>
      </geometry>
      <material name="part_6_material">
        <color rgba="0.231373 0.380392 0.705882 1.0"/>
      </material>
    </visual>
    <collision>
      <origin xyz="2.77556e-17 0 -0.184" rpy="1.5708 -1.52305e-30 -7.472e-31"/>
      <geometry>
        <mesh filename="package://climbbot3_description/climbbot3/assets/part_6.stl"/>
      </geometry>
    </collision>
  </link>
  <!-- Joint from part_4 to assembly_12 -->
  <joint name="r3_3" type="prismatic">
    <origin xyz="-3.05311e-16 0 0.002" rpy="-4.11758e-30 3.50237e-15 -4.08619e-15"/>
    <parent link="part_4"/>
    <child link="assembly_12"/>
    <axis xyz="0 0 1"/>
    <limit effort="1000" velocity="10" lower="-0.005" upper="0.134"/>
    <mimic joint="r3_1" multiplier="1.0" offset="0.00201"/>
  </joint>
  <!-- Joint from part_1 to part_4 -->
  <joint name="r3_2" type="prismatic">
    <origin xyz="3.05311e-16 0 5.71765e-15" rpy="6.79253e-26 -1.9984e-15 -1.98441e-15"/>
    <parent link="part_1"/>
    <child link="part_4"/>
    <axis xyz="0 0 1"/>
    <limit effort="1000" velocity="10" lower="-0.005" upper="0.134"/>
    <mimic joint="r3_1" multiplier="1.0" offset="0.00201"/>
  </joint>
  <!-- Joint from assembly_13 to part_1 -->
  <joint name="r3_1" type="prismatic">
    <origin xyz="-0.035 -0.1745 -0.03171" rpy="1.5708 1.5708 0"/>
    <parent link="assembly_13"/>
    <child link="part_1"/>
    <axis xyz="0 0 1"/>
    <limit effort="1000" velocity="10" lower="-0.007" upper="0.132"/>
  </joint>
  <!-- Joint from assembly_9 to assembly_13 -->
  <joint name="r2" type="revolute">
    <origin xyz="-0.0005625 0.0598 -0.0323" rpy="1.5708 -1.5708 0"/>
    <parent link="assembly_9"/>
    <child link="assembly_13"/>
    <axis xyz="0 0 1"/>
    <limit effort="1000" velocity="10" lower="-1.5708" upper="1.5708"/>
  </joint>
  <!-- Joint from assembly_7 to assembly_9 -->
  <joint name="r1" type="revolute">
    <origin xyz="0.180853 0.1192 0.0286776" rpy="-5.78703e-29 5.42099e-27 -5.24704e-14"/>
    <parent link="assembly_7"/>
    <child link="assembly_9"/>
    <axis xyz="0 0 1"/>
    <limit effort="1000" velocity="10" lower="-1.5708" upper="1.5708"/>
  </joint>
  <!-- Link assembly_8 -->
  <link name="assembly_8">
    <inertial>
      <origin xyz="0.0103209 -0.0152428 -0.0306495" rpy="0 0 0"/>
      <mass value="0.117321"/>
      <inertia ixx="5.92776e-05" ixy="2.61663e-07" ixz="1.58401e-07" iyy="3.37166e-05" iyz="-2.68677e-06" izz="6.38198e-05"/>
    </inertial>
    <!-- Part servomount1_2 -->
    <visual>
      <origin xyz="-0.0393875 -0.042 -0.112549" rpy="-1.5708 1.5708 0"/>
      <geometry>
        <mesh filename="package://climbbot3_description/climbbot3/assets/servomount1.stl"/>
      </geometry>
      <material name="servomount1_2_material">
        <color rgba="0.231373 0.380392 0.705882 1.0"/>
      </material>
    </visual>
    <collision>
      <origin xyz="-0.0393875 -0.042 -0.112549" rpy="-1.5708 1.5708 0"/>
      <geometry>
        <mesh filename="package://climbbot3_description/climbbot3/assets/servomount1.stl"/>
      </geometry>
    </collision>
    <!-- Part ds3225mg_servo_25kg_4_8_6_8v_3 -->
    <visual>
      <origin xyz="0 0 0" rpy="0 -0 -7.99449e-48"/>
      <geometry>
        <mesh filename="package://climbbot3_description/climbbot3/assets/ds3225mg_servo_25kg_4_8_6_8v.stl"/>
      </geometry>
      <material name="ds3225mg_servo_25kg_4_8_6_8v_3_material">
        <color rgba="0.615686 0.811765 0.929412 1.0"/>
      </material>
    </visual>
    <collision>
      <origin xyz="0 0 0" rpy="0 -0 -7.99449e-48"/>
      <geometry>
        <mesh filename="package://climbbot3_description/climbbot3/assets/ds3225mg_servo_25kg_4_8_6_8v.stl"/>
      </geometry>
    </collision>
    <!-- Part ds3225mg_servo_25kg_4_8_6_8v_4 -->
    <visual>
      <origin xyz="0.0005625 -0.0598 -0.0323" rpy="1.5708 -6.83843e-14 -6.49951e-14"/>
      <geometry>
        <mesh filename="package://climbbot3_description/climbbot3/assets/ds3225mg_servo_25kg_4_8_6_8v.stl"/>
      </geometry>
      <material name="ds3225mg_servo_25kg_4_8_6_8v_4_material">
        <color rgba="0.615686 0.811765 0.929412 1.0"/>
      </material>
    </visual>
    <collision>
      <origin xyz="0.0005625 -0.0598 -0.0323" rpy="1.5708 -6.83843e-14 -6.49951e-14"/>
      <geometry>
        <mesh filename="package://climbbot3_description/climbbot3/assets/ds3225mg_servo_25kg_4_8_6_8v.stl"/>
      </geometry>
    </collision>
  </link>
  <!-- Link assembly_10 -->
  <link name="assembly_10">
    <inertial>
      <origin xyz="0.0497031 -0.0466015 -0.0305736" rpy="0 0 0"/>
      <mass value="0.316303"/>
      <inertia ixx="0.00107615" ixy="-0.000141447" ixz="1.56092e-05" iyy="0.000345634" iyz="-1.31899e-05" izz="0.00123511"/>
    </inertial>
    <!-- Part servo_arm_horn_25t_aluminium_4 -->
    <visual>
      <origin xyz="-4.33681e-19 0 0.00105" rpy="3.14159 9.16604e-30 -4.07924e-31"/>
      <geometry>
        <mesh filename="package://climbbot3_description/climbbot3/assets/servo_arm_horn_25t_aluminium.stl"/>
      </geometry>
      <material name="servo_arm_horn_25t_aluminium_4_material">
        <color rgba="0.231373 0.380392 0.705882 1.0"/>
      </material>
    </visual>
    <collision>
      <origin xyz="-4.33681e-19 0 0.00105" rpy="3.14159 9.16604e-30 -4.07924e-31"/>
      <geometry>
        <mesh filename="package://climbbot3_description/climbbot3/assets/servo_arm_horn_25t_aluminium.stl"/>
      </geometry>
    </collision>
    <!-- Part part_22_2 -->
    <visual>
      <origin xyz="0.0984855 0.00775 0.0101353" rpy="3.14159 0.40526 2.3667e-14"/>
      <geometry>
        <mesh filename="package://climbbot3_description/climbbot3/assets/part_22.stl"/>
      </geometry>
      <material name="part_22_2_material">
        <color rgba="0.972549 0.529412 0.00392157 1.0"/>
      </material>
    </visual>
    <collision>
      <origin xyz="0.0984855 0.00775 0.0101353" rpy="3.14159 0.40526 2.3667e-14"/>
      <geometry>
        <mesh filename="package://climbbot3_description/climbbot3/assets/part_22.stl"/>
      </geometry>
    </collision>
    <!-- Part part_17_2 -->
    <visual>
      <origin xyz="0.0365086 0.0055 -0.0200863" rpy="3.14159 -1.31266 1.96048e-12"/>
      <geometry>
        <mesh filename="package://climbbot3_description/climbbot3/assets/part_17.stl"/>
      </geometry>
      <material name="part_17_2_material">
        <color rgba="0.231373 0.380392 0.705882 1.0"/>
      </material>
    </visual>
    <collision>
      <origin xyz="0.0365086 0.0055 -0.0200863" rpy="3.14159 -1.31266 1.96048e-12"/>
      <geometry>
        <mesh filename="package://climbbot3_description/climbbot3/assets/part_17.stl"/>
      </geometry>
    </collision>
    <!-- Part part_23 -->
    <visual>
      <origin xyz="0.035 0.0055 0.06829" rpy="-3.14159 -1.5708 0"/>
      <geometry>
        <mesh filename="package://climbbot3_description/climbbot3/assets/part_23.stl"/>
      </geometry>
      <material name="part_23_material">
        <color rgba="0.917647 0.917647 0.917647 1.0"/>
      </material>
    </visual>
    <collision>
      <origin xyz="0.035 0.0055 0.06829" rpy="-3.14159 -1.5708 0"/>
      <geometry>
        <mesh filename="package://climbbot3_description/climbbot3/assets/part_23.stl"/>
      </geometry>
    </collision>
    <!-- Part spur_gear__22_teeth_2 -->
    <visual>
      <origin xyz="0.0984855 0.00775 0.0101353" rpy="3.14159 0.40526 2.34254e-14"/>
      <geometry>
        <mesh filename="package://climbbot3_description/climbbot3/assets/spur_gear__22_teeth.stl"/>
      </geometry>
      <material name="spur_gear__22_teeth_2_material">
        <color rgba="0.647059 0.647059 0.647059 1.0"/>
      </material>
    </visual>
    <collision>
      <origin xyz="0.0984855 0.00775 0.0101353" rpy="3.14159 0.40526 2.34254e-14"/>
      <geometry>
        <mesh filename="package://climbbot3_description/climbbot3/assets/spur_gear__22_teeth.stl"/>
      </geometry>
    </collision>
    <!-- Part spur_gear__23_teeth_2 -->
    <visual>
      <origin xyz="0.0349999 0.0335 -0.03171" rpy="-3.24185e-13 3.35287e-14 1.99396e-13"/>
      <geometry>
        <mesh filename="package://climbbot3_description/climbbot3/assets/spur_gear__23_teeth.stl"/>
      </geometry>
      <material name="spur_gear__23_teeth_2_material">
        <color rgba="0.615686 0.811765 0.929412 1.0"/>
      </material>
    </visual>
    <collision>
      <origin xyz="0.0349999 0.0335 -0.03171" rpy="-3.24185e-13 3.35287e-14 1.99396e-13"/>
      <geometry>
        <mesh filename="package://climbbot3_description/climbbot3/assets/spur_gear__23_teeth.stl"/>
      </geometry>
    </collision>
  </link>
  <!-- Link part_1_2 -->
  <link name="part_1_2">
    <inertial>
      <origin xyz="1.38472e-05 7.99599e-06 -0.0930872" rpy="0 0 0"/>
      <mass value="0.147279"/>
      <inertia ixx="0.000468632" ixy="3.96188e-08" ixz="1.39731e-07" iyy="0.000468614" iyz="6.37723e-08" izz="9.32972e-05"/>
    </inertial>
    <!-- Part part_1_2 -->
    <visual>
      <origin xyz="1.38778e-17 -1.38778e-17 -0.18" rpy="1.5708 5.07325e-31 -6.31089e-30"/>
      <geometry>
        <mesh filename="package://climbbot3_description/climbbot3/assets/part_1.stl"/>
      </geometry>
      <material name="part_1_2_material">
        <color rgba="0.615686 0.811765 0.929412 1.0"/>
      </material>
    </visual>
    <collision>
      <origin xyz="1.38778e-17 -1.38778e-17 -0.18" rpy="1.5708 5.07325e-31 -6.31089e-30"/>
      <geometry>
        <mesh filename="package://climbbot3_description/climbbot3/assets/part_1.stl"/>
      </geometry>
    </collision>
  </link>
  <!-- Link part_4_2 -->
  <link name="part_4_2">
    <inertial>
      <origin xyz="-3.06039e-07 -9.19232e-06 -0.0853006" rpy="0 0 0"/>
      <mass value="0.111767"/>
      <inertia ixx="0.000294934" ixy="-2.53805e-10" ixz="-3.63143e-09" iyy="0.000294916" iyz="-7.85505e-08" izz="5.00057e-05"/>
    </inertial>
    <!-- Part part_4_2 -->
    <visual>
      <origin xyz="0 -6.93889e-18 -0.18" rpy="1.5708 3.1765e-31 -4.91298e-30"/>
      <geometry>
        <mesh filename="package://climbbot3_description/climbbot3/assets/part_4.stl"/>
      </geometry>
      <material name="part_4_2_material">
        <color rgba="0.647059 0.647059 0.647059 1.0"/>
      </material>
    </visual>
    <collision>
      <origin xyz="0 -6.93889e-18 -0.18" rpy="1.5708 3.1765e-31 -4.91298e-30"/>
      <geometry>
        <mesh filename="package://climbbot3_description/climbbot3/assets/part_4.stl"/>
      </geometry>
    </collision>
  </link>
  <!-- Link assembly_11 -->
  <link name="assembly_11">
    <inertial>
      <origin xyz="-2.19526e-06 0.00540004 -0.0130509" rpy="0 0 0"/>
      <mass value="0.156296"/>
      <inertia ixx="0.000776836" ixy="-5.10682e-10" ixz="-8.26793e-08" iyy="0.000766427" iyz="-6.26958e-05" izz="5.24529e-05"/>
    </inertial>
    <!-- Part gripper_hook_2 -->
    <visual>
      <origin xyz="-1.38778e-17 0.0419282 0.045" rpy="9.02058e-15 -1.4988e-15 4.43517e-15"/>
      <geometry>
        <mesh filename="package://climbbot3_description/climbbot3/assets/gripper_hook.stl"/>
      </geometry>
      <material name="gripper_hook_2_material">
        <color rgba="0.615686 0.811765 0.929412 1.0"/>
      </material>
    </visual>
    <collision>
      <origin xyz="-1.38778e-17 0.0419282 0.045" rpy="9.02058e-15 -1.4988e-15 4.43517e-15"/>
      <geometry>
        <mesh filename="package://climbbot3_description/climbbot3/assets/gripper_hook.stl"/>
      </geometry>
    </collision>
    <!-- Part part_6_2 -->
    <visual>
      <origin xyz="0 6.93889e-18 -0.184" rpy="1.5708 1.56787e-31 7.25459e-31"/>
      <geometry>
        <mesh filename="package://climbbot3_description/climbbot3/assets/part_6.stl"/>
      </geometry>
      <material name="part_6_2_material">
        <color rgba="0.231373 0.380392 0.705882 1.0"/>
      </material>
    </visual>
    <collision>
      <origin xyz="0 6.93889e-18 -0.184" rpy="1.5708 1.56787e-31 7.25459e-31"/>
      <geometry>
        <mesh filename="package://climbbot3_description/climbbot3/assets/part_6.stl"/>
      </geometry>
    </collision>
  </link>
  <!-- Joint from part_4_2 to assembly_11 -->
  <joint name="l3_3" type="prismatic">
    <origin xyz="-7.07767e-16 -6.93889e-18 0.002" rpy="1.4988e-15 4.4964e-15 1.4988e-15"/>
    <parent link="part_4_2"/>
    <child link="assembly_11"/>
    <axis xyz="0 0 1"/>
    <limit effort="1000" velocity="10" lower="-0.005" upper="0.134"/>
    <mimic joint="l3_1" multiplier="1.0" offset="0.00201"/>
  </joint>
  <!-- Joint from part_1_2 to part_4_2 -->
  <joint name="l3_2" type="prismatic">
    <origin xyz="7.21645e-16 0 2.55351e-15" rpy="-1.58419e-27 -9.21485e-15 1.38143e-15"/>
    <parent link="part_1_2"/>
    <child link="part_4_2"/>
    <axis xyz="0 0 1"/>
    <limit effort="1000" velocity="10" lower="-0.005" upper="0.134"/>
    <mimic joint="l3_1" multiplier="1.0" offset="0.00201"/>
  </joint>
  <!-- Joint from assembly_10 to part_1_2 -->
  <joint name="l3_1" type="prismatic">
    <origin xyz="0.035 -0.1745 -0.03171" rpy="1.5708 -1.5708 0"/>
    <parent link="assembly_10"/>
    <child link="part_1_2"/>
    <axis xyz="0 0 1"/>
    <limit effort="1000" velocity="10" lower="-0.007" upper="0.132"/>
  </joint>
  <!-- Joint from assembly_8 to assembly_10 -->
  <joint name="l2" type="revolute">
    <origin xyz="0.0005625 -0.0598 -0.0323" rpy="-1.5708 1.5708 0"/>
    <parent link="assembly_8"/>
    <child link="assembly_10"/>
    <axis xyz="0 0 1"/>
    <limit effort="1000" velocity="10" lower="-1.5708" upper="1.5708"/>
  </joint>
  <!-- Joint from assembly_7 to assembly_8 -->
  <joint name="l1" type="revolute">
    <origin xyz="0.180853 0.0191578 0.0286776" rpy="1.50377e-30 5.32967e-18 4.55474e-14"/>
    <parent link="assembly_7"/>
    <child link="assembly_8"/>
    <axis xyz="0 0 1"/>
    <limit effort="1000" velocity="10" lower="-1.5708" upper="1.5708"/>
  </joint>

<!-- First end effector modifications -->
<link name="l3_roll">
<visual>
    <origin xyz="0 0 0" rpy="0 0 0"/>
    <geometry>
    <cylinder radius="0.001" length="0.001"/>
    </geometry>
</visual>
<inertial>
    <mass value="0.001"/>
    <inertia ixx="0.001" ixy="0" ixz="0" iyy="0.001" iyz="0" izz="0.001"/>
</inertial>
</link>

<joint name="l3_roll_joint" type="revolute">
<parent link="assembly_11"/>
<child link="l3_roll"/>
<origin xyz="0 0 0.05" rpy="0 0 0"/>
<axis xyz="1 0 0"/>
<limit effort="1000.0" lower="-3.14159" upper="3.14159" velocity="0.5"/>
</joint>

<link name="l3_pitch">
<visual>
    <origin xyz="0 0 0" rpy="0 0 0"/>
    <geometry>
    <cylinder radius="0.001" length="0.001"/>
    </geometry>
</visual>
<inertial>
    <mass value="0.001"/>
    <inertia ixx="0.001" ixy="0" ixz="0" iyy="0.001" iyz="0" izz="0.001"/>
</inertial>
</link>

<joint name="l3_pitch_joint" type="revolute">
<parent link="l3_roll"/>
<child link="l3_pitch"/>
<origin xyz="0 0 0" rpy="0 0 0"/>
<axis xyz="0 1 0"/>
<limit effort="1000.0" lower="-3.14159" upper="3.14159" velocity="0.5"/>
</joint>

<link name="l3_yaw">
<visual>
    <origin xyz="0 0 0" rpy="0 0 0"/>
    <geometry>
    <cylinder radius="0.001" length="0.001"/>
    </geometry>
</visual>
<inertial>
    <mass value="0.001"/>
    <inertia ixx="0.001" ixy="0" ixz="0" iyy="0.001" iyz="0" izz="0.001"/>
</inertial>
</link>

<joint name="l3_yaw_joint" type="revolute">
<parent link="l3_pitch"/>
<child link="l3_yaw"/>
<origin xyz="0 0 0" rpy="0 0 0"/>
<axis xyz="0 0 1"/>
<limit effort="1000.0" lower="-3.14159" upper="3.14159" velocity="0.5"/>
</joint>


<!-- Second end effector modifications -->
<link name="r3_roll">
<visual>
    <origin xyz="0 0 0" rpy="0 0 0"/>
    <geometry>
    <cylinder radius="0.001" length="0.001"/>
    </geometry>
</visual>
<inertial>
    <mass value="0.001"/>
    <inertia ixx="0.001" ixy="0" ixz="0" iyy="0.001" iyz="0" izz="0.001"/>
</inertial>
</link>

<joint name="r3_roll_joint" type="revolute">
<parent link="assembly_12"/>
<child link="r3_roll"/>
<origin xyz="0 0 0.05" rpy="0 0 0"/>
<axis xyz="1 0 0"/>
<limit effort="1000.0" lower="-3.14159" upper="3.14159" velocity="0.5"/>
</joint>

<link name="r3_pitch">
<visual>
    <origin xyz="0 0 0" rpy="0 0 0"/>
    <geometry>
    <cylinder radius="0.001" length="0.001"/>
    </geometry>
</visual>
<inertial>
    <mass value="0.001"/>
    <inertia ixx="0.001" ixy="0" ixz="0" iyy="0.001" iyz="0" izz="0.001"/>
</inertial>
</link>

<joint name="r3_pitch_joint" type="revolute">
<parent link="r3_roll"/>
<child link="r3_pitch"/>
<origin xyz="0 0 0" rpy="0 0 0"/>
<axis xyz="0 1 0"/>
<limit effort="1000.0" lower="-3.14159" upper="3.14159" velocity="0.5"/>
</joint>

<link name="r3_yaw">
<visual>
    <origin xyz="0 0 0" rpy="0 0 0"/>
    <geometry>
    <cylinder radius="0.001" length="0.001"/>
    </geometry>
</visual>
<inertial>
    <mass value="0.001"/>
    <inertia ixx="0.001" ixy="0" ixz="0" iyy="0.001" iyz="0" izz="0.001"/>
</inertial>
</link>

<joint name="r3_yaw_joint" type="revolute">
<parent link="r3_pitch"/>
<child link="r3_yaw"/>
<origin xyz="0 0 0" rpy="0 0 0"/>
<axis xyz="0 0 1"/>
<limit effort="1000.0" lower="-3.14159" upper="3.14159" velocity="0.5"/>
</joint>
</robot>
